Workbook

Sheet 00_overview
A1: Soul v1.1-alpha 概览
A2: 浙江杭海新城控股集团有限公司 | 2024 | CNY | lgfv
A4: 公司名称 | B4: 浙江杭海新城控股集团有限公司 | C4: 审计意见 | D4: 未识别 | E4: 报告类型 | F4: a_share_full_report
A6: 执行摘要
A7: 公司仍保持“平台公司+开发经营”双重属性，报告期末资产总额 809.95 亿元，负债总额 530.00 亿元，归母所有者权益 247.81 亿元。
A8: 收入端表面平稳，全年营业收入 12.51 亿元、净利润 0.81 亿元，但经营现金流净额为 -68.73 亿元，利润与现金回收明显背离。
A9: 存货 610.31 亿元、应收账款 19.58 亿元、其他应收款 61.07 亿元，资产结构高度偏向土地开发、代建和平台往来。
A10: 有息负债规模较大，短期借款 67.44 亿元，一年内到期非流动负债 27.09 亿元，应付债券 79.14 亿元，流动性依赖再融资和政府支持。
A12: 关键风险
A13: 风险 | B13: 等级 | C13: 说明 | D13: 证据
A14: 再融资依赖 | B14: 高 | C14: 短期借款和一年内到期债务合计规模较大，期末现金短债比仅约 0.28 倍。 | D14: # 五、合并财务报表项目注释 # (一) 合并资产负债表项目注释 # 1. 货币资金 # (1) 明细情况 项目 期末数 期初数 库存现金 7,953.43 26,404.10 银行存款 1,917,588,357.41 2,288,119,772.34 其他货币资金 143,679,696.95 114,916,2… | E14: EVD-0009
A15: 低效占资 | B15: 高 | C15: 存货、预付款和往来款占用资金量大，经营现金流持续为负，资产周转压力高。 | D15: 项目名称 期末数 期初数 土地一级开发项目 40,121,108,899.97 32,972,588,134.89 代建项目 13,542,806,227.42 12,618,894,844.40 保障安置房 2,328,279,411.70 2,220,168,821.39 小计 55,992,194,539.09… | E15: EVD-0010
A16: 关联与政府项目依赖 | B16: 中 | C16: 应收、预付、租赁和往来关系大量集中于政府及国有平台，外部市场化回款属性偏弱。 | D16: # 五、合并财务报表项目注释 # (一) 合并资产负债表项目注释 # 1. 货币资金 # (1) 明细情况 项目 期末数 期初数 库存现金 7,953.43 26,404.10 银行存款 1,917,588,357.41 2,288,119,772.34 其他货币资金 143,679,696.95 114,916,2… | E16: EVD-0009
A17: 或有负债与担保 | B17: 高 | C17: 对外担保余额较大，且涉及多家平台公司与长期到期项目，尾部风险需要持续跟踪。 | D17: 项目名称 期末数 期初数 土地一级开发项目 40,121,108,899.97 32,972,588,134.89 代建项目 13,542,806,227.42 12,618,894,844.40 保障安置房 2,328,279,411.70 2,220,168,821.39 小计 55,992,194,539.09… | E17: EVD-0010
A18: 融资成本侵蚀利润 | B18: 高 | C18: 财务费用率接近四分之一，净利息负担仍处高位，融资成本持续消耗利润空间。 | D18: # 五、合并财务报表项目注释 # (一) 合并资产负债表项目注释 # 1. 货币资金 # (1) 明细情况 项目 期末数 期初数 库存现金 7,953.43 26,404.10 银行存款 1,917,588,357.41 2,288,119,772.34 其他货币资金 143,679,696.95 114,916,2… | E18: EVD-0009
A20: 报告亮点
A21: 收入与利润 | B21: 营业收入 12.51 亿元，营业利润 0.92 亿元，净利润 0.81 亿元，仍能维持正向利润，但利润质量受政府补助和非经常性因素影响较大。
A22: 现金流 | B22: 经营活动现金流净额 -68.73 亿元，投资活动净流出 8.80 亿元，全年主要依靠筹资活动净流入 73.88 亿元对冲。
A23: 资产结构 | B23: 存货 610.31 亿元，其中开发成本 559.92 亿元；投资性房地产 45.50 亿元，在建工程 13.85 亿元，典型平台开发资产占比高。
A24: 融资成本 | B24: 财务费用 3.09 亿元，利息支出 3.12 亿元，财务费用率约 24.72%，说明融资成本对利润形成持续挤压。
A25: 负债结构 | B25: 短期借款 67.44 亿元、长期借款 277.45 亿元、应付债券 79.14 亿元，融资结构以银行及债券融资为主。

Sheet 01_kpi_dashboard
A1: KPI Dashboard
A2: 固定骨架模块 01
A4: 分类 | B4: 指标 | C4: 当前值 | D4: 单位 | E4: 风险 | F4: 来源 | G4: 对比 | H4: 证据
A5: 杠杆 | B5: 资产总额 | C5: ='RAW_INPUTS'!$B$11 | D5: 亿元 | E5: 中 | F5: 合并资产负债表 | G5: 较上年增加 116.04 亿元 | H5: EVD-0009
B6: 负债总额 | C6: ='RAW_INPUTS'!$B$12 | D6: 亿元 | E6: 高 | F6: 合并资产负债表 | G6: 负债率约 65.4% | H6: EVD-0009
B7: 权益占比 | C7: =IFERROR(('RAW_INPUTS'!$B$11-'RAW_INPUTS'!$B$12)/'RAW_INPUTS'!$B$11*100,"") | E7: 中 | F7: 合并资产负债表 | G7: 归母权益 247.81 亿元 | H7: EVD-0009
B8: 流动比率 | C8: =IFERROR('RAW_INPUTS'!$B$30/'RAW_INPUTS'!$B$31,"") | D8: x | E8: 低 | F8: 资产负债表推算 | G8: 流动资产 722.16 亿元 / 流动负债 131.83 亿元 | H8: EVD-0009
A9: 偿债 | B9: 现金及现金等价物 | C9: ='RAW_INPUTS'!$B$40 | D9: 亿元 | E9: 中 | F9: 现金流量表 | G9: 期末现金 19.18 亿元 | H9: EVD-0009
B10: 现金短债比 | C10: =IFERROR('RAW_INPUTS'!$B$40/'RAW_INPUTS'!$B$42,"") | D10: x | E10: 高 | F10: 计算指标 | G10: 低于 1 倍 | H10: EVD-0009
B11: 一年内到期债务 | C11: ='RAW_INPUTS'!$B$17 | D11: 亿元 | E11: 高 | F11: 长期负债到期结构 | G11: 一年内到期债务较大 | H11: EVD-0009
B12: 计息负债合计 | C12: ='RAW_INPUTS'!$B$18 | D12: 亿元 | E12: 高 | F12: 筹资活动负债变动表 | G12: 以银行借款和债券为主 | H12: EVD-0009
A13: 盈利 | B13: 营业收入 | C13: ='RAW_INPUTS'!$B$19 | D13: 亿元 | E13: 中 | F13: 合并利润表 | G13: 同比增长 15.1% | H13: EVD-0009
B14: 净利润 | C14: ='RAW_INPUTS'!$B$20 | D14: 亿元 | E14: 中 | F14: 合并利润表 | G14: 净利率约 6.5% | H14: EVD-0009
B15: 归母净利润 | C15: ='RAW_INPUTS'!$B$21 | D15: 亿元 | E15: 中 | F15: 合并利润表 | G15: 少数股东损益贡献较大 | H15: EVD-0009
B16: 毛利率 | C16: =IFERROR(('RAW_INPUTS'!$B$32-'RAW_INPUTS'!$B$33)/'RAW_INPUTS'!$B$32*100,"") | E16: 高 | F16: 收入成本测算 | G16: 收入 12.51 亿元 / 成本 12.12 亿元 | H16: EVD-0009
A17: 现金流 | B17: 经营活动现金流净额 | C17: ='RAW_INPUTS'!$B$23 | D17: 亿元 | E17: 高 | F17: 合并现金流量表 | G17: 持续为负 | H17: EVD-0009
B18: 投资活动现金流净额 | C18: ='RAW_INPUTS'!$B$24 | D18: 亿元 | E18: 中 | F18: 合并现金流量表 | G18: 继续投向项目与股权 | H18: EVD-0009
B19: 筹资活动现金流净额 | C19: ='RAW_INPUTS'!$B$25 | D19: 亿元 | E19: 高 | F19: 合并现金流量表 | G19: 依赖外部融资补流 | H19: EVD-0009
B20: 受限资金 | C20: ='RAW_INPUTS'!$B$26 | D20: 亿元 | E20: 中 | F20: 受限资产注释 | G20: 资金受限约 1.44 亿元 | H20: EVD-0009

Sheet 02_financial_summary
A1: Financial Summary
A2: 固定骨架模块 02
A3: 以合并报表三大表和核心附注为依据，单位统一换算为亿元展示。
A5: 资产负债表摘要
A6: 项目 | B6: 期间 | C6: 数值 | D6: 单位 | E6: 说明
A7: 资产总计 | B7: 2024-12-31 | C7: ='RAW_INPUTS'!$B$27 | D7: 亿元 | E7: 资产端继续扩张。
A8: 负债合计 | B8: 2024-12-31 | C8: ='RAW_INPUTS'!$B$28 | D8: 亿元 | E8: 有息负债与往来负债占比高。
A9: 归母所有者权益 | B9: 2024-12-31 | C9: ='RAW_INPUTS'!$B$29 | D9: 亿元 | E9: 资本公积和未分配利润构成主体。
A10: 流动资产合计 | B10: 2024-12-31 | C10: ='RAW_INPUTS'!$B$30 | D10: 亿元 | E10: 流动资产占比极高。
A11: 流动负债合计 | B11: 2024-12-31 | C11: ='RAW_INPUTS'!$B$31 | D11: 亿元 | E11: 一年内到期债务压力仍然存在。
A13: 利润表摘要
A14: 项目 | B14: 期间 | C14: 数值 | D14: 单位 | E14: 说明
A15: 营业收入 | B15: 2024 | C15: ='RAW_INPUTS'!$B$32 | D15: 亿元 | E15: 同比增长。
A16: 营业成本 | B16: 2024 | C16: ='RAW_INPUTS'!$B$33 | D16: 亿元 | E16: 成本接近收入。
A17: 营业利润 | B17: 2024 | C17: ='RAW_INPUTS'!$B$34 | D17: 亿元 | E17: 主业盈利但空间较薄。
A18: 净利润 | B18: 2024 | C18: ='RAW_INPUTS'!$B$35 | D18: 亿元 | E18: 利润主要受补助和资产处置影响。
A19: 归母净利润 | B19: 2024 | C19: ='RAW_INPUTS'!$B$36 | D19: 亿元 | E19: 少数股东损益占比较高。
A21: 现金流量表摘要
A22: 项目 | B22: 期间 | C22: 数值 | D22: 单位 | E22: 说明
A23: 经营活动现金流净额 | B23: 2024 | C23: ='RAW_INPUTS'!$B$37 | D23: 亿元 | E23: 经营造血能力偏弱。
A24: 投资活动现金流净额 | B24: 2024 | C24: ='RAW_INPUTS'!$B$38 | D24: 亿元 | E24: 继续投入项目和股权。
A25: 筹资活动现金流净额 | B25: 2024 | C25: ='RAW_INPUTS'!$B$39 | D25: 亿元 | E25: 融资补流特征明显。
A26: 期末现金及现金等价物 | B26: 2024-12-31 | C26: ='RAW_INPUTS'!$B$40 | D26: 亿元 | E26: 剔除受限资金后缓冲有限。

Sheet 03_debt_profile
A1: Debt Profile
A2: 固定骨架模块 03
A4: 债务总览
A5: 项目 | B5: 期间 | C5: 数值 | D5: 单位 | E5: 备注 | F5: 证据
A6: 计息负债合计 | B6: 2024-12-31 | C6: ='RAW_INPUTS'!$B$41 | D6: 亿元 | E6: 含借款、债券、租赁负债与长期应付款。 | F6: EVD-0009
A7: 短期借款 | B7: 2024-12-31 | C7: ='RAW_INPUTS'!$B$42 | D7: 亿元 | E7: 保证借款占主导。 | F7: EVD-0009
A8: 一年内到期非流动负债 | B8: 2024-12-31 | C8: ='RAW_INPUTS'!$B$43 | D8: 亿元 | E8: 短期化压力较明显。 | F8: EVD-0009
A9: 应付债券 | B9: 2024-12-31 | C9: ='RAW_INPUTS'!$B$44 | D9: 亿元 | E9: 境内外债券并行。 | F9: EVD-0009
A11: 期限结构
A12: 项目 | B12: 期间 | C12: 数值 | D12: 单位 | E12: 备注 | F12: 证据
A13: 1年内 | B13: 2024-12-31 | C13: ='RAW_INPUTS'!$B$45 | D13: 元 | E13: 到期压力较高。 | F13: EVD-0009
A14: 1-3年 | B14: 2024-12-31 | C14: ='RAW_INPUTS'!$B$46 | D14: 元 | E14: 按现有披露口径难以直接拆分。 | F14: EVD-0009
A15: 3年以上 | B15: 2024-12-31 | C15: ='RAW_INPUTS'!$B$47 | D15: 元 | E15: 由债券与借款滚动形成。 | F15: EVD-0009
A17: 融资结构
A18: 项目 | B18: 期间 | C18: 数值 | D18: 单位 | E18: 备注 | F18: 证据
A19: 银行及担保借款 | B19: 2024 | C19: ='RAW_INPUTS'!$B$48 | E19: 仍是融资主轴。 | F19: EVD-0009
A20: 债券融资 | B20: 2024 | C20: ='RAW_INPUTS'!$B$49 | E20: 资本市场融资占比高。 | F20: EVD-0009
A21: 其他融资 | B21: 2024 | C21: ='RAW_INPUTS'!$B$50 | E21: 包含租赁和长期应付款。 | F21: EVD-0009
A23: 利率结构
A24: 项目 | B24: 期间 | C24: 数值 | D24: 单位 | E24: 说明
A25: 利息支出 | B25: 2024 | C25: ='RAW_INPUTS'!$B$51 | D25: 亿元 | E25: 财务费用压力较大。
A26: 债务平均利率 | B26: 2024 | C26: =IFERROR('RAW_INPUTS'!$B$51/(('RAW_INPUTS'!$B$2+'RAW_INPUTS'!$B$3)/2)*100,"") | E26: 按期初期末平均有息负债与利息支出测算。
A27: 债务评论
A28: 标签 | B28: 详情 | C28: 来源 | D28: 证据
A29: 负债扩张 | B29: 报告期内短期借款、长期借款和债券余额均保持高位，融资结构对再融资窗口依赖明显。 | E29: 年报附注与三大表一致 | F29: EVD-0009
A30: 期限错配 | B30: 一年内到期负债规模较大，而经营现金流为负，期限错配风险仍是核心关注点。 | E30: 年报附注与现金流量表一致 | F30: EVD-0009

Sheet 04_liquidity_and_covenants
A1: Liquidity And Covenants
A2: 固定骨架模块 04
A4: 现金指标
A5: 项目 | B5: 期间 | C5: 数值 | D5: 单位 | E5: 备注 | F5: 证据
A6: 现金及现金等价物 | C6: - | F6: EVD-0009
A7: 受限资金 | C7: - | F7: EVD-0009
A8: 现金短债比 | C8: - | F8: EVD-0009
A9: 经营现金流 | C9: - | F9: EVD-0009
A11: 授信与债务窗口
A12: 项目 | B12: 期间 | C12: 数值 | D12: 单位 | E12: 备注 | F12: 证据
A13: 公开授信披露 | C13: - | F13: EVD-0009
A15: 受限资产
A16: 项目 | B16: 期间 | C16: 数值 | D16: 单位 | E16: 备注 | F16: 证据
A17: 受限资产总额 | C17: - | F17: EVD-0009
A18: 受限货币资金 | C18: - | F18: EVD-0009
A20: 财务契约
A21: 条目 | B21: 状态 | C21: 受限债务 | D21: 单位 | E21: 来源 | F21: 证据
A22: 财务契约披露 | B22: unknown | C22: - | E22: 未单列披露 | F22: EVD-0009
A24: 流动性观察
A25: 经营性资金占用 | B25: 应收、预付和其他应收合计规模大，叠加存货 610.31 亿元，导致经营性占资持续高位。 | F25: EVD-0010
A26: 回款与补流 | B26: 经营现金流持续为负，筹资现金流为正，说明当前仍需要外部融资维持项目推进。 | F26: EVD-0009

Sheet 05_financing_cost
A1: 融资成本计算
A2: 专题模块
A4: 2024 年财务费用 3.09 亿元，利息支出 3.12 亿元、利息收入 0.13 亿元，净利息负担约 3.00 亿元；财务费用率约 24.72%，融资成本对利润侵蚀明显。
A7: 融资成本口径
A8: 指标 | B8: 数值 | C8: 单位 | D8: 来源 | E8: 证据
A9: 财务费用 | B9: ='RAW_INPUTS'!$B$53 | C9: 亿元 | D9: 财务费用注释 | E9: EVD-0009
A10: 利息支出 | B10: ='RAW_INPUTS'!$B$54 | C10: 亿元 | D10: 财务费用注释 | E10: EVD-0009
A11: 利息收入 | B11: ='RAW_INPUTS'!$B$55 | C11: 亿元 | D11: 财务费用注释 | E11: EVD-0009
A12: 净利息负担 | B12: =IFERROR('RAW_INPUTS'!$B$54-'RAW_INPUTS'!$B$55,"") | C12: 亿元 | D12: 财务费用注释测算 | E12: EVD-0009
A13: 财务费用/营业收入 | B13: =IFERROR('RAW_INPUTS'!$B$53/'RAW_INPUTS'!$B$32*100,"") | D13: 收入与费用测算 | E13: EVD-0009
A14: 利息支出/平均有息负债 | B14: =IFERROR('RAW_INPUTS'!$B$54/(('RAW_INPUTS'!$B$2+'RAW_INPUTS'!$B$3)/2)*100,"") | D14: 按期初期末平均有息负债测算 | E14: EVD-0009
A15: 判断
A16: 指标 | B16: 数值 | C16: 单位 | D16: 来源 | E16: 证据
A17: 结论 | B17: 融资成本仍是利润表的重要消耗项，且主要依赖再融资滚动消化。 | D17: 专题判断 | E17: EVD-0009
A19: 风险信号
A20: 信号 | B20: 等级 | C20: 影响 | D20: 证据
A21: 融资成本侵蚀利润 | B21: 高 | C21: 财务费用率约 24.72%，融资成本压力高。 | D21: 财务费用 309,211,034.42；利息支出 312,473,821.71

Sheet 06_platform_special
A1: 城投专题分析
A2: 专题模块
A4: 公司城投属性突出，开发存货几乎全部由政府项目构成，应收、其他应收和预付款项也高度集中于政府及国有平台，市场化资产占比很低。
A7: 城投业务拆分
A8: 指标 | B8: 数值 | C8: 单位 | D8: 来源 | E8: 证据
A9: 存货总额 | B9: ='RAW_INPUTS'!$B$59 | C9: 亿元 | D9: 存货注释 | E9: EVD-0010
A10: 政府相关库存资产 | B10: =IFERROR('RAW_INPUTS'!$B$5-'RAW_INPUTS'!$B$4,"") | C10: 亿元 | D10: 按项目拆分 | E10: EVD-0010
A11: 市场相关库存资产 | B11: ='RAW_INPUTS'!$B$4 | C11: 亿元 | D11: 按项目拆分 | E11: EVD-0010
A12: 政府相关库存占比 | B12: =IFERROR('RAW_INPUTS'!$B$60/'RAW_INPUTS'!$B$5*100,"") | D12: 按项目拆分 | E12: EVD-0010
A13: 土地一级开发 | B13: ='RAW_INPUTS'!$B$63 | C13: 亿元 | D13: 开发成本拆分 | E13: EVD-0010
A14: 代建项目 | B14: ='RAW_INPUTS'!$B$64 | C14: 亿元 | D14: 开发成本拆分 | E14: EVD-0010
A15: 保障安置房成本 | B15: ='RAW_INPUTS'!$B$65 | C15: 亿元 | D15: 开发成本拆分 | E15: EVD-0010
A16: 政府往来与资产端
A17: 指标 | B17: 数值 | C17: 单位 | D17: 来源 | E17: 证据
A18: 应收账款政府组合 | B18: ='RAW_INPUTS'!$B$66 | C18: 亿元 | D18: 应收账款组合 | E18: EVD-0018
A19: 应收账款政府组合占比 | B19: =IFERROR('RAW_INPUTS'!$B$66/'RAW_INPUTS'!$B$8*100,"") | D19: 应收账款组合 | E19: EVD-0018
A20: 其他应收款政府组合 | B20: ='RAW_INPUTS'!$B$68 | C20: 亿元 | D20: 其他应收款组合 | E20: EVD-0018
A21: 其他应收款政府组合占比 | B21: =IFERROR('RAW_INPUTS'!$B$68/'RAW_INPUTS'!$B$9*100,"") | D21: 其他应收款组合 | E21: EVD-0018
A22: 预付款项政府对象 | B22: ='RAW_INPUTS'!$B$70 | C22: 亿元 | D22: 预付款项前五名 | E22: EVD-0009
A23: 预付款项政府对象占比 | B23: =IFERROR('RAW_INPUTS'!$B$70/'RAW_INPUTS'!$B$10*100,"") | D23: 预付款项前五名 | E23: EVD-0009
A24: 判断
A25: 指标 | B25: 数值 | C25: 单位 | D25: 来源 | E25: 证据
A26: 结论 | B26: 资产端政府化程度高，项目结算与财政安排决定回款节奏，市场化业务占比很低。 | D26: 专题判断 | E26: EVD-0010, EVD-0017
A28: 风险信号
A29: 信号 | B29: 等级 | C29: 影响 | D29: 证据
A30: 政府回款集中 | B30: 高 | C30: 结算与回款节奏高度依赖政府和平台。 | D30: 应收政府及国有控股单位款项组合 16,007,137,972.90；其他应收款政府组合 34,865,744,503.90
A31: 市场化资产占比低 | B31: 中 | C31: 存货几乎全部由城投项目构成。 | D31: 政府相关库存资产 609.784347729；市场相关库存资产 0.5297904293

Sheet 99_evidence_index
A1: Evidence Index
A2: 固定骨架模块 99
A4: 证据ID | B4: 字段路径 | C4: Sheet | D4: 证据片段 | E4: 文档 | F4: 章节 | G4: 附注 | H4: 置信度
A5: EVD-0001 | B5: chapter_records.1.evidence | C5: 00_overview | D5: # 一、公司基本情况 浙江杭海新城控股集团有限公司（以下简称公司或本公司）原名海宁高新区科创中心有限公司（以下简称科创中心），科创中心原由海宁仰山实业集团有限公司(以下简称仰山实业)发起设立，设立时注册资本 500万元，并于 2015年 9 月 25 日在海宁市市场监督管理局登记注册；经历次增资及股权转让，公司股东变… | E5: chapter_records | F5: 1 一、公司基本情况 | G5: 1 | H5: medium
A6: EVD-0002 | B6: chapter_records.1.evidence | C6: 00_overview | D6: 浙江杭海新城控股集团有限公司（以下简称公司或本公司）原名海宁高新区科创中心有限公司（以下简称科创中心），科创中心原由海宁仰山实业集团有限公司(以下简称仰山实业)发起设立，设立时注册资本 500万元，并于 2015年 9 月 25 日在海宁市市场监督管理局登记注册。经历次增资及股权转让，公司股东变更为海宁市人民政府国有… | E6: chapter_records | F6: 1 一、公司基本情况 | G6: 1 | H6: medium
A7: EVD-0003 | B7: chapter_records.2.evidence | C7: 00_overview | D7: # 二、财务报表的编制基础 # (一) 编制基础 本公司财务报表以持续经营为编制基础；# (二) 持续经营能力评价 本公司不存在导致对报告期末起 12个月内的持续经营能力产生重大疑虑的事项或情况 | E7: chapter_records | F7: 2 二、财务报表的编制基础 | G7: 2 | H7: medium
A8: EVD-0004 | B8: chapter_records.2.evidence | C8: 00_overview | D8: 本公司不存在导致对报告期末起 12个月内的持续经营能力产生重大疑虑的事项或情况。 | E8: chapter_records | F8: 2 二、财务报表的编制基础 | G8: 2 | H8: medium
A9: EVD-0005 | B9: chapter_records.3.evidence | C9: 00_overview | D9: # 三、重要会计政策和会计估计 # (一) 遵循企业会计准则的声明 本财务报表符合企业会计准则的要求，真实、完整地反映了企业的财务状况、经营成果和现金流量等有关信息；# (二) 会计期间 会计年度自公历 1 月 1 日起至 12 月 31 日止 | E9: chapter_records | F9: 3 三、重要会计政策和会计估计 | G9: 3 | H9: medium
A10: EVD-0006 | B10: chapter_records.3.evidence | C10: 00_overview | D10: [注]根据海宁市人民政府《关于印发海宁市主要污染物排污权总量指标管理办法（试行）的通知》(海政发〔2017〕54 号)有关精神，公司取得的排污权可永久性使用，故无需进行摊销 | E10: chapter_records | F10: 3 三、重要会计政策和会计估计 | G10: 3 | H10: medium
A11: EVD-0007 | B11: chapter_records.4.evidence | C11: 00_overview | D11: # 四、税（费）项 # (一) 主要税种及税率 税 种 计税依据 税 率 增值税 房产销售收入、租赁收入、建筑服务收入等，按税法规定计算的销售货物和应税劳务收入为基础按适用征收率计缴 3%、5%、6%、9%、13% 房产税 从价计征的，按房产原值一次减除30%后余值的1.2%计缴；从租计征的，按租金收入的12%计缴… | E11: chapter_records | F11: 4 四、税（费）项 | G11: 4 | H11: medium
A12: EVD-0008 | B12: chapter_records.4.evidence | C12: 00_overview | D12: 税 种 计税依据 税 率 增值税 房产销售收入、租赁收入、建筑服务收入等，按税法规定计算的销售货物和应税劳务收入为基础按适用征收率计缴 3%、5%、6%、9%、13% 房产税 从价计征的，按房产原值一次减除30%后余值的1.2%计缴；从租计征的，按租金收入的12%计缴 1.2%、12% 城市维护建设税 实际缴纳的流转… | E12: chapter_records | F12: 4 四、税（费）项 | G12: 4 | H12: medium
A13: EVD-0009 | B13: chapter_records.5.evidence | C13: 00_overview | D13: # 五、合并财务报表项目注释 # (一) 合并资产负债表项目注释 # 1. 货币资金 # (1) 明细情况 项目 期末数 期初数 库存现金 7,953.43 26,404.10 银行存款 1,917,588,357.41 2,288,119,772.34 其他货币资金 143,679,696.95 114,916,2… | E13: chapter_records | F13: 5 五、合并财务报表项目注释 | G13: 5 | H13: medium
A14: EVD-0010 | B14: chapter_records.5.evidence | C14: 00_overview | D14: 项目名称 期末数 期初数 土地一级开发项目 40,121,108,899.97 32,972,588,134.89 代建项目 13,542,806,227.42 12,618,894,844.40 保障安置房 2,328,279,411.70 2,220,168,821.39 小计 55,992,194,539.09… | E14: chapter_records | F14: 5 五、合并财务报表项目注释 | G14: 5 | H14: medium
A15: EVD-0011 | B15: chapter_records.6.evidence | C15: 00_overview | D15: # 六、在其他主体中的权益 # (一) 企业集团的构成 1. 公司将下述子公司纳入合并财务报表范围 序号 子公司全称 子公司类型 子公司简称 1 海宁仰山实业集团有限公司 全资子公司 仰山实业 1-1 海宁仰山资产管理有限公司 仰山实业之全资子公司 仰山资产 1-2 海宁仰山开发建设有限公司 仰山实业之全资子公司 仰… | E15: chapter_records | F15: 6 六、在其他主体中的权益 | G15: 6 | H15: medium
... A26: EVD-0022 | B26: chapter_records.11.evidence | C26: 00_overview | D26: 项目 期末数 期初数 账面余额 减值准备 账面价值 账面余额 减值准备 账面价值 对子公司投资 13,143,341,814.55 13,143,341,814.55 11,143,341,814.55 11,143,341,814.55 合计 13,143,341,814.55 13,143,341,814.55… | E26: chapter_records | F26: 11 十一、母公司财务报表主要项目注释 | G26: 11 | H26: medium

Sheet RAW_INPUTS
A1: 键 | B1: 数值 | C1: 单位 | D1: 说明
A2: 期初有息负债合计 | B2: 383.0788 | C2: 亿元 | D2: 公式辅助输入
A3: 期末有息负债合计 | B3: 476.92928 | C3: 亿元 | D3: 公式辅助输入
A4: 市场相关库存资产 | B4: 0.52979043 | C4: 亿元 | D4: 公式辅助输入
A5: 存货总额 | B5: 610.31414 | C5: 亿元 | D5: 公式辅助输入
A6: 库存商品 | B6: 0.000478265 | C6: 亿元 | D6: 公式辅助输入
A7: 商品房、商业地产 | B7: 0.52904071 | C7: 亿元 | D7: 公式辅助输入
A8: 应收账款总额 | B8: 19.756357 | C8: 亿元 | D8: 公式辅助输入
A9: 其他应收款总额 | B9: 61.068541 | C9: 亿元 | D9: 公式辅助输入
A10: 预付款项总额 | B10: 8.1705179 | C10: 亿元 | D10: 公式辅助输入
A11: 资产总额 | B11: 809.94787 | C11: 亿元 | D11: 合并资产负债表
A12: 负债总额 | B12: 530.00389 | C12: 亿元 | D12: 合并资产负债表
A13: 权益占比 | B13: 34.6 | D13: 合并资产负债表
A14: 流动比率 | B14: 5.48 | C14: x | D14: 资产负债表推算
A15: 现金及现金等价物 | B15: 19.175386 | C15: 亿元 | D15: 现金流量表
A16: 现金短债比 | B16: 0.28 | C16: x | D16: 计算指标
A17: 一年内到期债务 | B17: 27.094716 | C17: 亿元 | D17: 长期负债到期结构
A18: 计息负债合计 | B18: 476.92928 | C18: 亿元 | D18: 筹资活动负债变动表
A19: 营业收入 | B19: 12.512902 | C19: 亿元 | D19: 合并利润表
A20: 净利润 | B20: 0.80948768 | C20: 亿元 | D20: 合并利润表
A21: 归母净利润 | B21: 0.29568947 | C21: 亿元 | D21: 合并利润表
A22: 毛利率 | B22: 3.1 | D22: 收入成本测算
A23: 经营活动现金流净额 | B23: -68.72633 | C23: 亿元 | D23: 合并现金流量表
A24: 投资活动现金流净额 | B24: -8.7990376 | C24: 亿元 | D24: 合并现金流量表
A25: 筹资活动现金流净额 | B25: 73.879282 | C25: 亿元 | D25: 合并现金流量表
A26: 受限资金 | B26: 1.4373737 | C26: 亿元 | D26: 受限资产注释
A27: 资产总计 | B27: 809.94787 | C27: 亿元 | D27: 资产端继续扩张。
A28: 负债合计 | B28: 530.00389 | C28: 亿元 | D28: 有息负债与往来负债占比高。
A29: 归母所有者权益 | B29: 247.80669 | C29: 亿元 | D29: 资本公积和未分配利润构成主体。
A30: 流动资产合计 | B30: 722.15572 | C30: 亿元 | D30: 流动资产占比极高。
A31: 流动负债合计 | B31: 131.83351 | C31: 亿元 | D31: 一年内到期债务压力仍然存在。
A32: 营业收入 | B32: 12.512902 | C32: 亿元 | D32: 同比增长。
A33: 营业成本 | B33: 12.120047 | C33: 亿元 | D33: 成本接近收入。
A34: 营业利润 | B34: 0.91717047 | C34: 亿元 | D34: 主业盈利但空间较薄。
... A47: 3年以上 | B47: 0 | C47: 元 | D47: 由债券与借款滚动形成。
A48: 银行及担保借款 | B48: 72.3 | D48: 仍是融资主轴。
A49: 债券融资 | B49: 16.6 | D49: 资本市场融资占比高。
A50: 其他融资 | B50: 11.1 | D50: 包含租赁和长期应付款。
A51: 利息支出 | B51: 3.1247382 | C51: 亿元 | D51: 财务费用压力较大。
A52: 债务平均利率 | B52: 7.27 | D52: 按期初期末平均有息负债与利息支出测算。
...
